Workbook

Sheet GEVEv2_full_ano
B1: gene | C1: contig | D1: source | E1: start | F1: end | G1: strand | H1: ncldv_marker | I1: marker_evalue | J1: marker_score | K1: gvog | L1: gvog_evalue | M1: gvog_score | N1: eggnog_ogs | O1: eggnog_name | P1: eggnog_desc | Q1: cog_cat | R1: max_annot_lvl | S1: eggnog_evalue | T1: eggnog_score | U1: eggnog_pfam | V1: pfam | W1: pfam_desc | X1: pfam_score | Y1: hhpred_n_hits | Z1: hhpred_n_regions | AA1: top_targets | AB1: top_descriptions | AC1: avg_query_cover | AD1: max_probability | AE1: mod_6mA | AF1: cluster | AG1: cds_per_transcript | AH1: introns_per_gene | AI1: introns | AJ1: NCLDV promoter | AK1: old_prodigal_id | AL1: comments
A2: 1 | B2: GEVEv2_1 | C2: contig_536 | D2: AUGUSTUS | E2: 2024298 | F2: 2028206 | G2: - | K2: GVOG01792 | L2: 8.1e-06 | M2: 20.5 | X2: 1303 | AF2: BVP | AG2: t1 (1) | AK2: contig_536_22 | AL2: =VLOOKUP(AK2,viral_genes!$C$2:$P$661,14, FALSE) -> TIR 1 start; early high expressed
A3: 2 | B3: GEVEv2_2 | C3: contig_536 | D3: Prodigal_v2.6.3 | E3: 2028209 | F3: 2028847 | G3: - | X3: 213 | AF3: BVP | AK3: contig_536_23 | AL3: =VLOOKUP(AK3,viral_genes!$C$2:$P$661,14, FALSE) -> early high expressed
A4: 3 | B4: GEVEv2_3 | C4: contig_536 | D4: AUGUSTUS | E4: 2033161 | F4: 2034048 | G4: - | X4: 178 | AE4: yes | AF4: BVP | AG4: t1 (4) | AH4: 3 | AI4: yes | AK4: contig_536_24-25 | AL4: =VLOOKUP(AK4,viral_genes!$C$2:$P$661,14, FALSE) -> #N/A
A5: 4 | B5: GEVEv2_4 | C5: contig_536 | D5: Prodigal_v2.6.3 | E5: 2034637 | F5: 2034777 | G5: + | X5: 47 | AE5: yes | AK5: contig_536_26 | AL5: =VLOOKUP(AK5,viral_genes!$C$2:$P$661,14, FALSE)
A6: 5 | B6: GEVEv2_5 | C6: contig_536 | D6: AUGUSTUS | E6: 2035275 | F6: 2038133 | G6: + | K6: GVOG01534 | L6: 2.8 | M6: 3.1 | X6: 492 | Y6: 9 | Z6: 6 | AA6: 5YVG_X; 6Y53_o; 7DVQ_4; 7OBR_u; 6Y50_q; 6Y5Q_q; 7BGB_H; 6GOS_A; 7OBQ_u | AB6: Transportin-1, RNA-binding protein FUS; Importin family, PROTEIN TRANSPORT, PROTEIN; 4.05A {Homo sapiens} | U2 small nuclear ribonucleoprotein A'; 17S U2 snRNP, SPLICING; 7.1A {Homo sapiens} | Pre-mRNA-processing-splicing factor 8, 116 kDa; spliceosome, minor spliceosome, Bact complex; HET: TPO, GTP, G5J, IHP, SEP; 2.89A {Homo sapiens} | SRP SRP receptor, co-translational protein; HET: MG, GDP; 2.8A {Canis lupus familiaris} | Splicing factor 3A subunit 3; 17S U2 snRNP, SPLICING; 4.1A {Homo sapiens} | U2 small nuclear ribonucleoprotein A'; 17S U2 snRNP, SPLICING; 7.1A {Homo sapiens} | Telomerase Cajal body protein 1; H/ACA RNP, ribonucleoprotein, complex, RNA; 3.39A {Homo sapiens} | Bacteriocin microcin B17, Microcin B17-processing; microcin, DNA gyrase, heterocyclization, posttranslational; HET: EDO, TOZ, OTZ, FMN; 2.1A {Escherichia coli str. K-12 substr. MG1655} | SRP SRP receptor, co-translational protein; HET: GTP, GNP; 3.9A {Canis lupus familiaris} | AC6: 0.187825299841593 | AD6: 97.67 | AE6: yes | AG6: t1 (10)| t2 (10) | AH6: 9 | AI6: yes | AK6: contig_536_27-30 | AL6: =VLOOKUP(AK6,viral_genes!$C$2:$P$661,14, FALSE) -> #N/A
A7: 6 | B7: GEVEv2_6 | C7: contig_536 | D7: Prodigal_v2.6.3 | E7: 2038470 | F7: 2038604 | G7: - | X7: 45 | AK7: contig_536_31 | AL7: =VLOOKUP(AK7,viral_genes!$C$2:$P$661,14, FALSE)
A8: 7 | B8: GEVEv2_7 | C8: contig_536 | D8: Prodigal_v2.6.3 | E8: 2038662 | F8: 2038952 | G8: - | X8: 97 | AK8: contig_536_32 | AL8: =VLOOKUP(AK8,viral_genes!$C$2:$P$661,14, FALSE)
A9: 8 | B9: GEVEv2_8 | C9: contig_536 | D9: AUGUSTUS | E9: 2040070 | F9: 2042203 | G9: + | K9: GVOGm1001 | L9: 0.037 | M9: 7.1 | X9: 568 | Y9: 1 | Z9: 1 | AA9: PF13388.9 | AB9: ; DUF4106 ; Protein of unknown function (DUF4106) | AC9: 0.155202821869489 | AD9: 81.45 | AE9: yes | AG9: t1 (4) | AH9: 3 | AI9: yes | AK9: contig_536_33-35 | AL9: =VLOOKUP(AK9,viral_genes!$C$2:$P$661,14, FALSE) -> #N/A
A10: 9 | B10: GEVEv2_9 | C10: contig_536 | D10: Prodigal_v2.6.3 | E10: 2042581 | F10: 2042712 | G10: - | X10: 44 | AK10: contig_536_36 | AL10: =VLOOKUP(AK10,viral_genes!$C$2:$P$661,14, FALSE)
A11: 10 | B11: GEVEv2_10 | C11: contig_536 | D11: Prodigal_v2.6.3 | E11: 2042985 | F11: 2043368 | G11: - | K11: GVOG01164 | L11: 0.87 | M11: 2.4 | X11: 128 | AK11: contig_536_37 | AL11: =VLOOKUP(AK11,viral_genes!$C$2:$P$661,14, FALSE)
A12: 11 | B12: GEVEv2_11 | C12: contig_536 | D12: Prodigal_v2.6.3 | E12: 2043368 | F12: 2043577 | G12: - | X12: 70 | AK12: contig_536_38 | AL12: =VLOOKUP(AK12,viral_genes!$C$2:$P$661,14, FALSE)
A13: 12 | B13: GEVEv2_12 | C13: contig_536 | D13: AUGUSTUS | E13: 2043578 | F13: 2044496 | G13: - | X13: 240 | AE13: yes | AF13: DVP | AG13: t1 (3) | AH13: 2 | AI13: yes | AK13: contig_536_39-40 | AL13: =VLOOKUP(AK13,viral_genes!$C$2:$P$661,14, FALSE) -> #N/A
A14: 13 | B14: GEVEv2_13 | C14: contig_536 | D14: AUGUSTUS | E14: 2044895 | F14: 2045514 | G14: + | X14: 135 | AE14: yes | AF14: BVP | AG14: t1 (2) | AH14: 1 | AI14: yes | AK14: contig_536_41-42 | AL14: =VLOOKUP(AK14,viral_genes!$C$2:$P$661,14, FALSE) -> #N/A
A15: 14 | B15: GEVEv2_14 | C15: contig_536 | D15: Prodigal_v2.6.3 | E15: 2046300 | F15: 2046890 | G15: + | X15: 197 | AF15: BVP | AK15: contig_536_43 | AL15: =VLOOKUP(AK15,viral_genes!$C$2:$P$661,14, FALSE)
A16: 15 | B16: GEVEv2_15 | C16: contig_536 | D16: Prodigal_v2.6.3 | E16: 2047033 | F16: 2050878 | G16: + | K16: GVOGm0180 | L16: 2.2e-09 | M16: 30.9 | V16: PF02037 | W16: SAP domain | X16: 1282 | Y16: 8 | Z16: 3 | AA16: 7C7L_B; 7L49_A; 7ODF_A; 6NY2_Y; 6NY3_Y; PF18516.4; 7OBR_u; 7OBQ_u | AB16: CRISPR-associated protein Cas14a.1/RNA/DNA Complex; Cas12f, Cas14, sgRNA, target DNA; 3.0A {uncultured archaeon} | Cas12f1/DNA Complex; CRISPR CAS, RNA BINDING PROTEIN;{unidentified} | CRISPR-Cas, RNA-guided endonuclease, R-loop, RNA; 2.7A {Phage #D} | CasX/DNA/RNA Complex; CasX, sgRNA, target DNA, CRISPR; 3.2A {Deltaproteobacteria bacterium} | CasX/DNA Complex; CasX, sgRNA, target DNA, CRISPR; 3.7A {Deltaproteobacteria bacterium} | ; RuvC_1 ; RuvC nuclease domain | SRP SRP receptor, co-translational protein; HET: MG, GDP; 2.8A {Canis lupus familiaris} | SRP SRP receptor, co-translational protein; HET: GTP, GNP; 3.9A {Canis lupus familiaris} | AC16: 0.080015612802498 | AD16: 96.77 | AJ16: yes | AK16: contig_536_44 | AL16: =VLOOKUP(AK16,viral_genes!$C$2:$P$661,14, FALSE) -> Fanzor_B_nuclease
A17: 16 | B17: GEVEv2_16 | C17: contig_536 | D17: Prodigal_v2.6.3 | E17: 2050869 | F17: 2051777 | G17: + | X17: 303 | AF17: DVP | AK17: contig_536_45 | AL17: =VLOOKUP(AK17,viral_genes!$C$2:$P$661,14, FALSE)
A18: 17 | B18: GEVEv2_17 | C18: contig_536 | D18: gmst | E18: 2051780 | F18: 2058806 | G18: + | K18: GVOG09276 | L18: 6.7 | M18: 0.2 | X18: 1260 | AE18: yes | AG18: t1 (10) | AH18: 9 | AI18: yes | AK18: contig_536_46-55 | AL18: =VLOOKUP(AK18,viral_genes!$C$2:$P$661,14, FALSE) -> #N/A
A19: 18 | B19: GEVEv2_18 | C19: contig_536 | D19: Prodigal_v2.6.3 | E19: 2058886 | F19: 2059026 | G19: + | X19: 47 | AK19: contig_536_56 | AL19: =VLOOKUP(AK19,viral_genes!$C$2:$P$661,14, FALSE)
A20: 19 | B20: GEVEv2_19 | C20: contig_536 | D20: AUGUSTUS | E20: 2060026 | F20: 2060606 | G20: + | X20: 72 | AE20: yes | AF20: BVP | AG20: t1 (4) | AH20: 3 | AI20: yes | AL20: =VLOOKUP(AK20,viral_genes!$C$2:$P$661,14, FALSE) -> #N/A
A21: 20 | B21: GEVEv2_20 | C21: contig_536 | D21: AUGUSTUS | E21: 2060789 | F21: 2061235 | G21: g | X21: 104 | AE21: yes | AF21: BVP | AG21: t1 (2) | AH21: 1 | AI21: yes | AL21: =VLOOKUP(AK21,viral_genes!$C$2:$P$661,14, FALSE) -> #N/A
A22: 21 | B22: GEVEv2_21 | C22: contig_536 | D22: AUGUSTUS | E22: 2062616 | F22: 2066455 | G22: + | K22: GVOGm1062 | L22: 1.7e-27 | M22: 91.8 | N22: COG0123@1|root,KOG1342@2759|Eukaryota,37MPC@33090|Viridiplantae,34H80@3041|Chlorophyta | P22: Belongs to the histone deacetylase family. HD Type 1 subfamily | Q22: B | R22: 33090|Viridiplantae | S22: 1.17e-54 | T22: 202 | U22: Hist_deacetyl | V22: PF00850 | W22: Histone deacetylase domain | X22: 1175 | Y22: 3 | Z22: 1 | AA22: 4BKX_B; 7AO8_B; 3MAX_A | AB22: METASTASIS-ASSOCIATED PROTEIN MTA1, HISTONE DEACETYLASE; TRANSCRIPTION, INOSITOL PHOSPHATE SIGNALLING, ELM2-SANT; HET: SO4; 3.0A {HOMO SAPIENS} | Methyl-CpG-binding domain protein 2, Metastasis-associated; Deacetylase, Complex, TRANSCRIPTION; HET: IHP; 4.5A {Homo sapiens} | Histone deacetylase 2 (E.C.3.5.1.98); Class 2, HDAC, foot pocket; HET: NHE, LLX; 2.05A {Homo sapiens} | AC22: 0.296422487223169 | AD22: 100 | AF22: BVP | AG22: t1 (3)| t2 (2) | AH22: 2 | AI22: yes | AK22: contig_536_58-59 | AL22: =VLOOKUP(AK22,viral_genes!$C$2:$P$661,14, FALSE) -> #N/A
A23: 22 | B23: GEVEv2_22 | C23: contig_536 | D23: gmst | E23: 2063639 | F23: 2064118 | G23: - | X23: 160 | AG23: t1 (1) | AL23: =VLOOKUP(AK23,viral_genes!$C$2:$P$661,14, FALSE) -> #N/A
A24: 23 | B24: GEVEv2_23 | C24: contig_536 | D24: Prodigal_v2.6.3 | E24: 2066529 | F24: 2067242 | G24: + | X24: 238 | AF24: BVP | AK24: contig_536_60 | AL24: =VLOOKUP(AK24,viral_genes!$C$2:$P$661,14, FALSE)
A25: 24 | B25: GEVEv2_24 | C25: contig_536 | D25: Prodigal_v2.6.3 | E25: 2067583 | F25: 2069337 | G25: + | X25: 585 | AE25: yes | AF25: DVP | AK25: contig_536_61 | AL25: =VLOOKUP(AK25,viral_genes!$C$2:$P$661,14, FALSE)
A26: 25 | B26: GEVEv2_25 | C26: contig_536 | D26: Prodigal_v2.6.3 | E26: 2069880 | F26: 2070125 | G26: + | K26: GVOG08592 | L26: 2.2e-05 | M26: 18.9 | X26: 82 | Y26: 4 | Z26: 2 | AA26: 5FJ9_I; 6TUT_I; 7AOC_I; PF04233.17 | AB26: DNA-DIRECTED RNA POLYMERASE III SUBUNIT; RNA POLYMERASE III, POL III; 4.6A {SACCHAROMYCES CEREVISIAE} | DNA-directed RNA polymerase III subunit; Transcription, RNA Polymerase III, Pol; 3.25A {Saccharomyces cerevisiae S288C} | DNA-directed RNA polymerase I subunit; TRANSCRIPTION;{Schizosaccharomyces pombe (strain 972 / ATCC 24843)} | ; Phage_Mu_F ; Phage Mu protein F like protein | AC26: 0.17283950617284 | AD26: 83.56 | AK26: contig_536_62 | AL26: =VLOOKUP(AK26,viral_genes!$C$2:$P$661,14, FALSE)
A27: 26 | B27: GEVEv2_26 | C27: contig_536 | D27: Prodigal_v2.6.3 | E27: 2070529 | F27: 2070774 | G27: + | X27: 82 | AE27: yes | AK27: contig_536_63 | AL27: =VLOOKUP(AK27,viral_genes!$C$2:$P$661,14, FALSE)
A28: 27 | B28: GEVEv2_27 | C28: contig_536 | D28: Prodigal_v2.6.3 | E28: 2070835 | F28: 2071419 | G28: + | X28: 195 | AE28: yes | AK28: contig_536_64 | AL28: =VLOOKUP(AK28,viral_genes!$C$2:$P$661,14, FALSE)
A29: 28 | B29: GEVEv2_28 | C29: contig_536 | D29: Prodigal_v2.6.3 | E29: 2071534 | F29: 2072646 | G29: + | K29: GVOG07877 | L29: 0.0031 | M29: 12.8 | X29: 371 | AE29: yes | AK29: contig_536_65 | AL29: =VLOOKUP(AK29,viral_genes!$C$2:$P$661,14, FALSE)
A30: 29 | B30: GEVEv2_29 | C30: contig_536 | D30: Prodigal_v2.6.3 | E30: 2072711 | F30: 2072863 | G30: + | X30: 51 | AK30: contig_536_66 | AL30: =VLOOKUP(AK30,viral_genes!$C$2:$P$661,14, FALSE)
A31: 30 | B31: GEVEv2_30 | C31: contig_536 | D31: Prodigal_v2.6.3 | E31: 2072835 | F31: 2073212 | G31: - | X31: 126 | AK31: contig_536_67 | AL31: =VLOOKUP(AK31,viral_genes!$C$2:$P$661,14, FALSE)
A32: 31 | B32: GEVEv2_31 | C32: contig_536 | D32: Prodigal_v2.6.3 | E32: 2073511 | F32: 2073654 | G32: + | X32: 48 | AK32: contig_536_68 | AL32: =VLOOKUP(AK32,viral_genes!$C$2:$P$661,14, FALSE)
A33: 32 | B33: GEVEv2_32 | C33: contig_536 | D33: Prodigal_v2.6.3 | E33: 2073786 | F33: 2074331 | G33: + | X33: 182 | AK33: contig_536_69 | AL33: =VLOOKUP(AK33,viral_genes!$C$2:$P$661,14, FALSE)
A34: 33 | B34: GEVEv2_33 | C34: contig_536 | D34: Prodigal_v2.6.3 | E34: 2074948 | F34: 2075100 | G34: + | X34: 51 | AF34: BVP | AK34: contig_536_70 | AL34: =VLOOKUP(AK34,viral_genes!$C$2:$P$661,14, FALSE) -> early high expressed
A35: 34 | B35: GEVEv2_34 | C35: contig_536 | D35: Prodigal_v2.6.3 | E35: 2076530 | F35: 2078923 | G35: + | V35: PF17879 | W35: DNA ligase C-terminal domain | X35: 798 | Y35: 6 | Z35: 3 | AA35: 6SC2_C; 6RLB_C; 3PGW_S; 6QX9_1K; 6QW6_5X; 6QX9_5X | AB35: DYNC2H1 variant protein; dynein, cilia, intraflagellar transport, complex; HET: ADP, ATP; 3.9A {Homo sapiens} | PROTEIN; dynein, cilia, intraflagellar transport, complex; 4.5A {Homo sapiens} | U1-A , U1-70K , Sm-D3; PROTEIN-RNA COMPLEX, U1 snRNA, Sm; 4.4A {Homo sapiens} | Splicing factor 3B subunit 4; RNP complex, splicing, RNA, protein; HET: M7M, GTP, IHP; 3.28A {Homo sapiens} | Small nuclear ribonucleoprotein Sm D1; RNP complex, splicing, RNA, protein; HET: M7M, GTP, IHP; 2.92A {Homo sapiens} | Splicing factor 3B subunit 4; RNP complex, splicing, RNA, protein; HET: M7M, GTP, IHP; 3.28A {Homo sapiens} | AC35: 0.240694270179841 | AD35: 97.37 | AF35: BVP | AK35: contig_536_71 | AL35: =VLOOKUP(AK35,viral_genes!$C$2:$P$661,14, FALSE) -> early high expressed
A36: 35 | B36: GEVEv2_35 | C36: contig_536 | D36: Prodigal_v2.6.3 | E36: 2079584 | F36: 2079799 | G36: - | X36: 72 | AF36: DVP | AK36: contig_536_72 | AL36: =VLOOKUP(AK36,viral_genes!$C$2:$P$661,14, FALSE)
A37: 36 | B37: GEVEv2_36 | C37: contig_536 | D37: AUGUSTUS | E37: 2080397 | F37: 2081495 | G37: - | X37: 182 | AE37: yes | AF37: DVP | AG37: t1 (6) | AH37: 5 | AI37: yes | AK37: contig_536_73 | AL37: =VLOOKUP(AK37,viral_genes!$C$2:$P$661,14, FALSE)
A38: 37 | B38: GEVEv2_37 | C38: contig_536 | D38: Prodigal_v2.6.3 | E38: 2082756 | F38: 2087447 | G38: - | K38: GVOG01434 | L38: 9.9e-11 | M38: 35.8 | N38: COG2801@1|root,KOG0017@2759|Eukaryota,37RRH@33090|Viridiplantae,3G8MV@35493|Streptophyta,3HVTZ@3699|Brassicales | P38: DNA RNA polymerases superfamily protein | Q38: L | R38: 35493|Streptophyta | S38: 2.11e-128 | T38: 431 | U38: RVP_2,RVT_1,Retrotrans_gag,rve,zf-CCHC | V38: PF13650 | PF00385 | PF13975 | PF17921 | PF17917 | PF17919 | PF00665 | PF00078 | W38: Aspartyl protease | Chromo (CHRromatin Organisation MOdifier) domain | gag-polyprotein putative aspartyl protease | Integrase zinc binding domain | RNase H-like domain found in reverse transcriptase | RNase H-like domain found in reverse transcriptase | Integrase core domain | Reverse transcriptase (RNA-dependent DNA polymerase) | X38: 1564 | Y38: 26 | Z38: 10 | AA38: 7Q5B_C; 4OL8_A; 4OL8_B; 7O0H_A; 7O0H_B; 7KSE_A; 1R0A_B; 5FRN_B; 3OYM_A; 6VOY_A; 3F9K_s; 3HPG_B; 3HPH_D; 1ZTW_A; 6B1R_A; 6MIH_A; PF05585.15; 2JYS_A; 1XYI_A; 1WD0_A; 1WVL_A; PF00336.21; 3S8I_A; 5HHL_A; 5HHJ_A; PF00078.30 | AC38: 0.181677247896058 | AD38: 100 | AF38: BVP | AK38: contig_536_74 | AL38: =VLOOKUP(AK38,viral_genes!$C$2:$P$661,14, FALSE) -> early high expressed
A39: 38 | B39: GEVEv2_38 | C39: contig_536 | D39: AUGUSTUS | E39: 2087496 | F39: 2089260 | G39: - | K39: GVOG01534 | L39: 1.5 | M39: 3.9 | X39: 256 | Y39: 12 | Z39: 5 | AA39: 5YVG_X; 3CW1_8; 3CW1_K; 3JCT_o; 7OHS_o; PF05918.14; 7OBR_u; 7OBQ_u; 1NJI_I; 1VQO_G; 2QA4_G; 6V7B_g | AB39: Transportin-1, RNA-binding protein FUS; Importin family, PROTEIN TRANSPORT, PROTEIN; 4.05A {Homo sapiens} | Spliceosomal U1 small nuclear ribonucleoprotein; pre-mRNA splicing, spliceosome, RNA-binding domain; 5.493A {Homo sapiens} | Spliceosomal U1 small nuclear ribonucleoprotein; pre-mRNA splicing, spliceosome, RNA-binding domain; 5.493A {Homo sapiens} | 60S ribosomal protein L2-A, 60S; pre-60S ribosome, RIBOSOME; HET: GTP; 3.08A {Saccharomyces cerevisiae S288c} | ribosomal assembly state, RIBOSOME; 4.38A {Saccharomyces cerevisiae S288C} | ; API5 ; Apoptosis inhibitory protein 5 (API5) | SRP SRP receptor, co-translational protein; HET: MG, GDP; 2.8A {Canis lupus familiaris} | SRP SRP receptor, co-translational protein; HET: GTP, GNP; 3.9A {Canis lupus familiaris} | large ribosomal subunit 50S; 50S, antibiotic, chloramphenicol, LSU, RIBOSOME; HET: NA, CL, MG, CLM; 3.0A {Haloarcula marismortui} SCOP: j.84.1.1 | 50S RIBOSOMAL SUBUNIT; ribosome 50S, PROTEIN-PROTEIN COMPLEX, RNA-RNA; HET: CL, 1MA, MG, PPU, UR3, PSU, OMU, SR, NA, OMG; 2.2A {Haloarcula marismortui} SCOP: j.84.1.1 | 50S RIBOSOMAL SUBUNIT; Large ribosomal subunit, Ribonucleoprotein, Ribosomal; HET: CL, MG, UR3, PSU, OMU, NA, OMG; 3.0A {Haloarcula marismortui} SCOP: j.84.1.1 | Structural protein VP1, Structural protein; helical symmetry, archaeal pilus, STRUCTURAL; 3.4A {Pyrobaculum filamentous virus 1} | AC39: 0.247058823529412 | AD39: 97.77 | AE39: yes | AF39: BVP | AG39: t1 (4) | AH39: 3 | AI39: yes | AK39: contig_536_75 | AL39: =VLOOKUP(AK39,viral_genes!$C$2:$P$661,14, FALSE) -> early high expressed
A40: 39 | B40: GEVEv2_39 | C40: contig_536 | D40: AUGUSTUS | E40: 2090146 | F40: 2092125 | G40: - | K40: GVOGm0180 | L40: 9.9e-62 | M40: 203.8 | N40: 2EG1T@1|root,2SM3P@2759|Eukaryota | P40: function. Source PGD | Q40: S | R40: 2759|Eukaryota | S40: 1.61e-119 | T40: 362 | X40: 660 | Y40: 7 | Z40: 3 | AA40: 7L49_A; 7C7L_B; 7ODF_A; 6NY2_Y; 6NY3_Y; 6XMG_A; PF07282.14 | AB40: Cas12f1/DNA Complex; CRISPR CAS, RNA BINDING PROTEIN;{unidentified} | CRISPR-associated protein Cas14a.1/RNA/DNA Complex; Cas12f, Cas14, sgRNA, target DNA; 3.0A {uncultured archaeon} | CRISPR-Cas, RNA-guided endonuclease, R-loop, RNA; 2.7A {Phage #D} | CasX/DNA/RNA Complex; CasX, sgRNA, target DNA, CRISPR; 3.2A {Deltaproteobacteria bacterium} | CasX/DNA Complex; CasX, sgRNA, target DNA, CRISPR; 3.7A {Deltaproteobacteria bacterium} | Cas12i/DNA Complex; CRISPR, HYDROLASE-RNA complex;{Lachnospiraceae bacterium ND2006} | ; OrfB_Zn_ribbon ; Putative transposase DNA-binding domain | AC40: 0.228267938434858 | AD40: 98.85 | AF40: DVP | AG40: t1 (1) | AJ40: yes | AK40: contig_536_76 | AL40: =VLOOKUP(AK40,viral_genes!$C$2:$P$661,14, FALSE) -> putative transposase; Fanzor_C_nuclease
...

Sheet viral_genes
A1: V2 | B1: mCG | D1: number | E1: GVOG | F1: virbit | G1: vdesc | H1: pfam | I1: pfambit | J1: eggNOG_OGs | K1: COG_category | L1: Functional category | M1: eggNOG_Desc | N1: HHPred | O1: hits_to_chlamy | P1: annotation_notes | Q1: protlength | R1: strand | S1: start | T1: end | U1: contig_start | V1: contig_end | W1: Proteome1_score | X1: Proteom2_score | Y1: MeanRPKM_cf20 | Z1: MeanCounts_cf20 | AA1: ExprCluster | AB1: Proteomics
C2: contig_536_1 | D2: 1 | E2: no_hit | F2: 0 | G2: no_hit | H2: no_hit | I2: 0 | Q2: 75 | R2: -1 | S2: 35 | T2: 259 | U2: =2003807+S2 -> 2003842 | V2: =2003808+T2 -> 2004067 | Y2: 0.10215924 | Z2: 0.2
C3: contig_536_2 | D3: 2 | E3: no_hit | F3: 0 | G3: no_hit | H3: no_hit | I3: 0 | O3: Cre11.g801258_4532.1 | Q3: 338 | R3: -1 | S3: 579 | T3: 1592 | U3: =2003807+S3 -> 2004386 | V3: =2003808+T3 -> 2005400 | Y3: 1.4216146 | Z3: 11.8
C4: contig_536_3 | D4: 3 | E4: no_hit | F4: 0 | G4: no_hit | H4: no_hit | I4: 0 | Q4: 144 | R4: 1 | S4: 3098 | T4: 3529 | U4: =2003807+S4 -> 2006905 | V4: =2003808+T4 -> 2007337 | Y4: 0.07121621 | Z4: 0.2
C5: contig_536_4 | D5: 4 | E5: no_hit | F5: 0 | G5: no_hit | H5: no_hit | I5: 0 | O5: Cre01.g800142_4532.1 | Q5: 204 | R5: -1 | S5: 3786 | T5: 4397 | U5: =2003807+S5 -> 2007593 | V5: =2003808+T5 -> 2008205 | Y5: 239.83192 | Z5: 957.7
C6: contig_536_5 | D6: 5 | E6: no_hit | F6: 0 | G6: no_hit | H6: no_hit | I6: 0 | Q6: 212 | R6: 1 | S6: 5604 | T6: 6239 | U6: =2003807+S6 -> 2009411 | V6: =2003808+T6 -> 2010047 | Y6: 0.2941414 | Z6: 1.3
C7: contig_536_6 | D7: 6 | E7: no_hit | F7: 0 | G7: no_hit | H7: no_hit | I7: 0 | Q7: 111 | R7: 1 | S7: 6343 | T7: 6675 | U7: =2003807+S7 -> 2010150 | V7: =2003808+T7 -> 2010483 | Y7: 1.0941073 | Z7: 2.4
C8: contig_536_7 | D8: 7 | E8: no_hit | F8: 0 | G8: no_hit | H8: no_hit | I8: 0 | O8: Cre01.g800142_4532.1 | Q8: 135 | R8: 1 | S8: 6984 | T8: 7388 | U8: =2003807+S8 -> 2010791 | V8: =2003808+T8 -> 2011196 | Y8: 706.63425 | Z8: 1864.6
C9: contig_536_8 | D9: 8 | E9: no_hit | F9: 0 | G9: no_hit | H9: no_hit | I9: 0 | Q9: 124 | R9: -1 | S9: 7700 | T9: 8071 | U9: =2003807+S9 -> 2011507 | V9: =2003808+T9 -> 2011879 | Y9: 35.998925 | Z9: 78.4
C10: contig_536_9 | D10: 9 | E10: no_hit | F10: 0 | G10: no_hit | H10: no_hit | I10: 0 | Q10: 68 | R10: 1 | S10: 8102 | T10: 8305 | U10: =2003807+S10 -> 2011909 | V10: =2003808+T10 -> 2012113 | Y10: 0.38770977 | Z10: 0.5
C11: contig_536_10 | D11: 10 | E11: no_hit | F11: 0 | G11: no_hit | H11: no_hit | I11: 0 | Q11: 140 | R11: 1 | S11: 8430 | T11: 8849 | U11: =2003807+S11 -> 2012237 | V11: =2003808+T11 -> 2012657 | Y11: 1.8584556 | Z11: 4.8
C12: contig_536_11 | D12: 11 | E12: no_hit | F12: 0 | G12: no_hit | H12: no_hit | I12: 0 | Q12: 87 | R12: 1 | S12: 8809 | T12: 9069 | U12: =2003807+S12 -> 2012616 | V12: =2003808+T12 -> 2012877 | Y12: 2.8228675 | Z12: 5.2 | AA12: pre_induc
C13: contig_536_12 | D13: 12 | E13: no_hit | F13: 0 | G13: no_hit | H13: no_hit | I13: 0 | Q13: 96 | R13: -1 | S13: 10637 | T13: 10924 | U13: =2003807+S13 -> 2014444 | V13: =2003808+T13 -> 2014732 | Y13: 210.96673 | Z13: 404.6
C14: contig_536_13 | D14: 13 | E14: no_hit | F14: 0 | G14: no_hit | H14: no_hit | I14: 0 | Q14: 122 | R14: 1 | S14: 11216 | T14: 11581 | U14: =2003807+S14 -> 2015023 | V14: =2003808+T14 -> 2015389 | Y14: 38.392109 | Z14: 94.1
C15: contig_536_14 | D15: 14 | E15: no_hit | F15: 0 | G15: no_hit | H15: no_hit | I15: 0 | Q15: 39 | R15: 1 | S15: 11836 | T15: 11952 | U15: =2003807+S15 -> 2015643 | V15: =2003808+T15 -> 2015760 | Y15: 3.5570678 | Z15: 2.5
C16: contig_536_15 | D16: 15 | E16: no_hit | F16: 0 | G16: no_hit | H16: no_hit | I16: 0 | O16: Cre15.g635717_4532.1 | Q16: 99 | R16: -1 | S16: 12352 | T16: 12648 | U16: =2003807+S16 -> 2016159 | V16: =2003808+T16 -> 2016456 | Y16: 53.53054 | Z16: 100.7
C17: contig_536_16 | D17: 16 | E17: no_hit | F17: 0 | G17: no_hit | H17: no_hit | I17: 0 | J17: 2E0K7@1 | K17: - | M17: - | Q17: 168 | R17: -1 | S17: 14143 | T17: 14646 | U17: =2003807+S17 -> 2017950 | V17: =2003808+T17 -> 2018454 | Y17: 203.10499 | Z17: 655.2 | AA17: post_induc
C18: contig_536_17 | D18: 17 | E18: no_hit | F18: 0 | G18: no_hit | H18: no_hit | I18: 0 | O18: Cre07.g800828_4532.1 | Q18: 182 | R18: -1 | S18: 14848 | T18: 15393 | U18: =2003807+S18 -> 2018655 | V18: =2003808+T18 -> 2019201 | Y18: 642.21406 | Z18: 2112.5 | AA18: post_induc
C19: contig_536_18 | D19: 18 | E19: no_hit | F19: 0 | G19: no_hit | H19: no_hit | I19: 0 | Q19: 126 | R19: -1 | S19: 16657 | T19: 17034 | U19: =2003807+S19 -> 2020464 | V19: =2003808+T19 -> 2020842 | Y19: 1076.7721 | Z19: 2657 | AA19: post_induc
C20: contig_536_19 | D20: 19 | E20: no_hit | F20: 0 | G20: no_hit | H20: no_hit | I20: 0 | Q20: 36 | R20: 1 | S20: 17214 | T20: 17321 | U20: =2003807+S20 -> 2021021 | V20: =2003808+T20 -> 2021129 | Y20: 149.03284 | Z20: 109.7
C21: contig_536_20 | D21: 20 | E21: no_hit | F21: 0 | G21: no_hit | H21: no_hit | I21: 0 | P21: early high expressed | Q21: 288 | R21: -1 | S21: 17549 | T21: 18412 | U21: =2003807+S21 -> 2021356 | V21: =2003808+T21 -> 2022220 | Y21: 52.410252 | Z21: 304.4 | AA21: pre_induc
C22: contig_536_21 | D22: 21 | E22: GVOGm1522 | F22: 10.15382 | G22: A helicase nuclease that prepares dsDNA breaks (DSB) for recombinational DNA repair. Binds to DSBs and unwinds DNA via a highly rapid and processive ATP-dependent bidirectional helicase activity. Unwinds dsDNA until it encounters a Chi (crossover hotspot instigator) sequence from the 3' direction. Cuts ssDNA a few nucleotides 3' to the Chi site. The properties and activities of the enzyme are changed at Chi. The Chi-altered holoenzyme produces a long 3'-ssDNA overhang and facilitates RecA-binding to the ssDNA for homologous DNA recombination and repair. Holoenzyme degrades any linearized DNA that is unable to undergo homologous recombination. In the holoenzyme this subunit has ssDNA-dependent ATPase and 5'-3' helicase activity. When added to pre-assembled RecBC greatly stimulates nuclease activity and augments holoenzyme processivity. Negatively regulates the RecA-loading ability of RecBCD | Helix-turn-helix domain | G-quadruplex DNA unwinding | unknown | Helix-hairpin-helix containing domain | unknown | four-way junction helicase activity | unknown | unknown | unknown | PIF1-like helicase | Superfamily I DNA and RNA helicases and helicase subunits | DNA helicase | A helicase nuclease that prepares dsDNA breaks (DSB) for recombinational DNA repair. Binds to DSBs and unwinds DNA via a highly rapid and processive ATP-dependent bidirectional helicase activity. Unwinds dsDNA until it encounters a Chi (crossover hotspot instigator) sequence from the 3' direction. Cuts ssDNA a few nucleotides 3' to the Chi site. The properties and activities of the enzyme are changed at Chi. The Chi-altered holoenzyme produces a long 3'-ssDNA overhang and facilitates RecA-binding to the ssDNA for homologous DNA recombination and repair. Holoenzyme degrades any linearized DNA that is unable to undergo homologous recombination. In the holoenzyme this subunit has ssDNA-dependent ATPase and 5'-3' helicase activity. When added to pre-assembled RecBC greatly stimulates nuclease activity and augments holoenzyme processivity. Negatively regulates the RecA-loading ability of RecBCD | H22: AAA_30 | I22: 13.70782 | P22: early high expressed | Q22: 300 | R22: -1 | S22: 18682 | T22: 19581 | U22: =2003807+S22 -> 2022489 | V22: =2003808+T22 -> 2023389 | Y22: 97.312297 | Z22: 611.6 | AA22: pre_induc
C23: contig_536_22 | D23: 22 | E23: no_hit | F23: 0 | G23: no_hit | H23: no_hit | I23: 0 | P23: TIR 1 start; early high expressed | Q23: 1303 | R23: -1 | S23: 20490 | T23: 24398 | U23: =2003807+S23 -> 2024297 | V23: =2003808+T23 -> 2028206 | Y23: 50.09561 | Z23: 1345.3 | AA23: pre_induc
C24: contig_536_23 | D24: 23 | E24: no_hit | F24: 0 | G24: no_hit | H24: no_hit | I24: 0 | P24: early high expressed | Q24: 213 | R24: -1 | S24: 24401 | T24: 25039 | U24: =2003807+S24 -> 2028208 | V24: =2003808+T24 -> 2028847 | Y24: 716.52141 | Z24: 3162 | AA24: pre_induc
C25: contig_536_24 | D25: 24 | E25: no_hit | F25: 0 | G25: no_hit | H25: no_hit | I25: 0 | Q25: 62 | R25: 1 | S25: 29503 | T25: 29688 | U25: =2003807+S25 -> 2033310 | V25: =2003808+T25 -> 2033496 | Y25: 0.8973179 | Z25: 1.3
C26: contig_536_25 | D26: 25 | E26: no_hit | F26: 0 | G26: no_hit | H26: no_hit | I26: 0 | Q26: 159 | R26: -1 | S26: 29653 | T26: 30129 | U26: =2003807+S26 -> 2033460 | V26: =2003808+T26 -> 2033937 | Y26: 24.079208 | Z26: 75.2
C27: contig_536_26 | D27: 26 | E27: no_hit | F27: 0 | G27: no_hit | H27: no_hit | I27: 0 | Q27: 47 | R27: 1 | S27: 30829 | T27: 30969 | U27: =2003807+S27 -> 2034636 | V27: =2003808+T27 -> 2034777 | Y27: 25.077644 | Z27: 24.7
C28: contig_536_27 | D28: 27 | E28: no_hit | F28: 0 | G28: no_hit | H28: no_hit | I28: 0 | Q28: 251 | R28: 1 | S28: 31467 | T28: 32219 | U28: =2003807+S28 -> 2035274 | V28: =2003808+T28 -> 2036027 | Y28: 18.947865 | Z28: 96.5
C29: contig_536_28 | D29: 28 | E29: no_hit | F29: 0 | G29: no_hit | H29: no_hit | I29: 0 | Q29: 57 | R29: -1 | S29: 32569 | T29: 32739 | U29: =2003807+S29 -> 2036376 | V29: =2003808+T29 -> 2036547 | Y29: 10.730382 | Z29: 12.6
C30: contig_536_29 | D30: 29 | E30: no_hit | F30: 0 | G30: no_hit | H30: no_hit | I30: 0 | P30: TIR 1 end | Q30: 95 | R30: -1 | S30: 33143 | T30: 33427 | U30: =2003807+S30 -> 2036950 | V30: =2003808+T30 -> 2037235 | Y30: 6.6609876 | Z30: 12.7
C31: contig_536_30 | D31: 30 | E31: no_hit | F31: 0 | G31: no_hit | H31: no_hit | I31: 0 | Q31: 116 | R31: 1 | S31: 33978 | T31: 34325 | U31: =2003807+S31 -> 2037785 | V31: =2003808+T31 -> 2038133 | Y31: 44.252759 | Z31: 103.1
C32: contig_536_31 | D32: 31 | E32: no_hit | F32: 0 | G32: no_hit | H32: no_hit | I32: 0 | Q32: 45 | R32: -1 | S32: 34662 | T32: 34796 | U32: =2003807+S32 -> 2038469 | V32: =2003808+T32 -> 2038604 | Y32: 95.093289 | Z32: 89.4
C33: contig_536_32 | D33: 32 | E33: no_hit | F33: 0 | G33: no_hit | H33: no_hit | I33: 0 | Q33: 97 | R33: -1 | S33: 34854 | T33: 35144 | U33: =2003807+S33 -> 2038661 | V33: =2003808+T33 -> 2038952 | Y33: 14.629262 | Z33: 28.4
C34: contig_536_33 | D34: 33 | E34: no_hit | F34: 0 | G34: no_hit | H34: no_hit | I34: 0 | Q34: 177 | R34: 1 | S34: 36556 | T34: 37086 | U34: =2003807+S34 -> 2040363 | V34: =2003808+T34 -> 2040894 | Y34: 8.1042005 | Z34: 29.6
C35: contig_536_34 | D35: 34 | E35: no_hit | F35: 0 | G35: no_hit | H35: no_hit | I35: 0 | Q35: 178 | R35: -1 | S35: 37338 | T35: 37871 | U35: =2003807+S35 -> 2041145 | V35: =2003808+T35 -> 2041679 | Y35: 5.9505576 | Z35: 22
C36: contig_536_35 | D36: 35 | E36: no_hit | F36: 0 | G36: no_hit | H36: no_hit | I36: 0 | Q36: 174 | R36: 1 | S36: 37874 | T36: 38395 | U36: =2003807+S36 -> 2041681 | V36: =2003808+T36 -> 2042203 | Y36: 11.680902 | Z36: 37.3
C37: contig_536_36 | D37: 36 | E37: no_hit | F37: 0 | G37: no_hit | H37: no_hit | I37: 0 | Q37: 44 | R37: -1 | S37: 38773 | T37: 38904 | U37: =2003807+S37 -> 2042580 | V37: =2003808+T37 -> 2042712 | Y37: 0.481057 | Z37: 0.5
C38: contig_536_37 | D38: 37 | E38: no_hit | F38: 0 | G38: no_hit | H38: no_hit | I38: 0 | Q38: 128 | R38: -1 | S38: 39177 | T38: 39560 | U38: =2003807+S38 -> 2042984 | V38: =2003808+T38 -> 2043368 | Y38: 12077.39 | Z38: 29703.4
C39: contig_536_38 | D39: 38 | E39: no_hit | F39: 0 | G39: no_hit | H39: no_hit | I39: 0 | Q39: 70 | R39: -1 | S39: 39560 | T39: 39769 | U39: =2003807+S39 -> 2043367 | V39: =2003808+T39 -> 2043577 | Y39: 33.516795 | Z39: 47.1
C40: contig_536_39 | D40: 39 | E40: no_hit | F40: 0 | G40: no_hit | H40: no_hit | I40: 0 | Q40: 136 | R40: -1 | S40: 39770 | T40: 40177 | U40: =2003807+S40 -> 2043577 | V40: =2003808+T40 -> 2043985 | Y40: 30.688597 | Z40: 73.9 | AA40: post_induc
...

Sheet no anno
B1: number | C1: GVOG | D1: virbit | E1: vdesc | F1: pfam | G1: pfambit | H1: eggNOG_OGs | I1: COG_category | J1: Functional category | K1: eggNOG_Desc | L1: HHPred | M1: hits_to_chlamy | N1: annotation_notes | O1: protlength | P1: strand | Q1: start | R1: end | S1: contig_start | T1: contig_end | U1: Proteome1_score | V1: Proteom2_score | W1: MeanRPKM_cf20 | X1: MeanCounts_cf20 | Y1: ExprCluster | Z1: Proteomics
A2: contig_536_1 | B2: 1 | C2: no_hit | D2: 0 | E2: no_hit | F2: no_hit | G2: 0 | O2: 75 | P2: -1 | Q2: 35 | R2: 259 | S2: =2003807+Q2 -> 2003842 | T2: =2003808+R2 -> 2004067 | W2: 0.10215924 | X2: 0.2
A3: contig_536_2 | B3: 2 | C3: no_hit | D3: 0 | E3: no_hit | F3: no_hit | G3: 0 | M3: Cre11.g801258_4532.1 | O3: 338 | P3: -1 | Q3: 579 | R3: 1592 | S3: =2003807+Q3 -> 2004386 | T3: =2003808+R3 -> 2005400 | W3: 1.4216146 | X3: 11.8
A4: contig_536_3 | B4: 3 | C4: no_hit | D4: 0 | E4: no_hit | F4: no_hit | G4: 0 | O4: 144 | P4: 1 | Q4: 3098 | R4: 3529 | S4: =2003807+Q4 -> 2006905 | T4: =2003808+R4 -> 2007337 | W4: 0.07121621 | X4: 0.2
A5: contig_536_4 | B5: 4 | C5: no_hit | D5: 0 | E5: no_hit | F5: no_hit | G5: 0 | M5: Cre01.g800142_4532.1 | O5: 204 | P5: -1 | Q5: 3786 | R5: 4397 | S5: =2003807+Q5 -> 2007593 | T5: =2003808+R5 -> 2008205 | W5: 239.83192 | X5: 957.7
A6: contig_536_5 | B6: 5 | C6: no_hit | D6: 0 | E6: no_hit | F6: no_hit | G6: 0 | O6: 212 | P6: 1 | Q6: 5604 | R6: 6239 | S6: =2003807+Q6 -> 2009411 | T6: =2003808+R6 -> 2010047 | W6: 0.2941414 | X6: 1.3
A7: contig_536_6 | B7: 6 | C7: no_hit | D7: 0 | E7: no_hit | F7: no_hit | G7: 0 | O7: 111 | P7: 1 | Q7: 6343 | R7: 6675 | S7: =2003807+Q7 -> 2010150 | T7: =2003808+R7 -> 2010483 | W7: 1.0941073 | X7: 2.4
A8: contig_536_7 | B8: 7 | C8: no_hit | D8: 0 | E8: no_hit | F8: no_hit | G8: 0 | M8: Cre01.g800142_4532.1 | O8: 135 | P8: 1 | Q8: 6984 | R8: 7388 | S8: =2003807+Q8 -> 2010791 | T8: =2003808+R8 -> 2011196 | W8: 706.63425 | X8: 1864.6
A9: contig_536_8 | B9: 8 | C9: no_hit | D9: 0 | E9: no_hit | F9: no_hit | G9: 0 | O9: 124 | P9: -1 | Q9: 7700 | R9: 8071 | S9: =2003807+Q9 -> 2011507 | T9: =2003808+R9 -> 2011879 | W9: 35.998925 | X9: 78.4
A10: contig_536_9 | B10: 9 | C10: no_hit | D10: 0 | E10: no_hit | F10: no_hit | G10: 0 | O10: 68 | P10: 1 | Q10: 8102 | R10: 8305 | S10: =2003807+Q10 -> 2011909 | T10: =2003808+R10 -> 2012113 | W10: 0.38770977 | X10: 0.5
A11: contig_536_10 | B11: 10 | C11: no_hit | D11: 0 | E11: no_hit | F11: no_hit | G11: 0 | O11: 140 | P11: 1 | Q11: 8430 | R11: 8849 | S11: =2003807+Q11 -> 2012237 | T11: =2003808+R11 -> 2012657 | W11: 1.8584556 | X11: 4.8
A12: contig_536_11 | B12: 11 | C12: no_hit | D12: 0 | E12: no_hit | F12: no_hit | G12: 0 | O12: 87 | P12: 1 | Q12: 8809 | R12: 9069 | S12: =2003807+Q12 -> 2012616 | T12: =2003808+R12 -> 2012877 | W12: 2.8228675 | X12: 5.2 | Y12: pre_induc
A13: contig_536_12 | B13: 12 | C13: no_hit | D13: 0 | E13: no_hit | F13: no_hit | G13: 0 | O13: 96 | P13: -1 | Q13: 10637 | R13: 10924 | S13: =2003807+Q13 -> 2014444 | T13: =2003808+R13 -> 2014732 | W13: 210.96673 | X13: 404.6 | Z13: Yes
A14: contig_536_13 | B14: 13 | C14: no_hit | D14: 0 | E14: no_hit | F14: no_hit | G14: 0 | O14: 122 | P14: 1 | Q14: 11216 | R14: 11581 | S14: =2003807+Q14 -> 2015023 | T14: =2003808+R14 -> 2015389 | W14: 38.392109 | X14: 94.1
A15: contig_536_14 | B15: 14 | C15: no_hit | D15: 0 | E15: no_hit | F15: no_hit | G15: 0 | O15: 39 | P15: 1 | Q15: 11836 | R15: 11952 | S15: =2003807+Q15 -> 2015643 | T15: =2003808+R15 -> 2015760 | W15: 3.5570678 | X15: 2.5
A16: contig_536_15 | B16: 15 | C16: no_hit | D16: 0 | E16: no_hit | F16: no_hit | G16: 0 | M16: Cre15.g635717_4532.1 | O16: 99 | P16: -1 | Q16: 12352 | R16: 12648 | S16: =2003807+Q16 -> 2016159 | T16: =2003808+R16 -> 2016456 | W16: 53.53054 | X16: 100.7
A17: contig_536_16 | B17: 16 | C17: no_hit | D17: 0 | E17: no_hit | F17: no_hit | G17: 0 | H17: 2E0K7@1 | I17: - | K17: - | O17: 168 | P17: -1 | Q17: 14143 | R17: 14646 | S17: =2003807+Q17 -> 2017950 | T17: =2003808+R17 -> 2018454 | W17: 203.10499 | X17: 655.2 | Y17: post_induc
A18: contig_536_17 | B18: 17 | C18: no_hit | D18: 0 | E18: no_hit | F18: no_hit | G18: 0 | M18: Cre07.g800828_4532.1 | O18: 182 | P18: -1 | Q18: 14848 | R18: 15393 | S18: =2003807+Q18 -> 2018655 | T18: =2003808+R18 -> 2019201 | W18: 642.21406 | X18: 2112.5 | Y18: post_induc
A19: contig_536_18 | B19: 18 | C19: no_hit | D19: 0 | E19: no_hit | F19: no_hit | G19: 0 | O19: 126 | P19: -1 | Q19: 16657 | R19: 17034 | S19: =2003807+Q19 -> 2020464 | T19: =2003808+R19 -> 2020842 | W19: 1076.7721 | X19: 2657 | Y19: post_induc
A20: contig_536_19 | B20: 19 | C20: no_hit | D20: 0 | E20: no_hit | F20: no_hit | G20: 0 | O20: 36 | P20: 1 | Q20: 17214 | R20: 17321 | S20: =2003807+Q20 -> 2021021 | T20: =2003808+R20 -> 2021129 | W20: 149.03284 | X20: 109.7
A21: contig_536_20 | B21: 20 | C21: no_hit | D21: 0 | E21: no_hit | F21: no_hit | G21: 0 | N21: early high expressed | O21: 288 | P21: -1 | Q21: 17549 | R21: 18412 | S21: =2003807+Q21 -> 2021356 | T21: =2003808+R21 -> 2022220 | W21: 52.410252 | X21: 304.4 | Y21: pre_induc
A22: contig_536_21 | B22: 21 | C22: GVOGm1522 | D22: 10.15382 | E22: A helicase nuclease that prepares dsDNA breaks (DSB) for recombinational DNA repair. Binds to DSBs and unwinds DNA via a highly rapid and processive ATP-dependent bidirectional helicase activity. Unwinds dsDNA until it encounters a Chi (crossover hotspot instigator) sequence from the 3' direction. Cuts ssDNA a few nucleotides 3' to the Chi site. The properties and activities of the enzyme are changed at Chi. The Chi-altered holoenzyme produces a long 3'-ssDNA overhang and facilitates RecA-binding to the ssDNA for homologous DNA recombination and repair. Holoenzyme degrades any linearized DNA that is unable to undergo homologous recombination. In the holoenzyme this subunit has ssDNA-dependent ATPase and 5'-3' helicase activity. When added to pre-assembled RecBC greatly stimulates nuclease activity and augments holoenzyme processivity. Negatively regulates the RecA-loading ability of RecBCD | Helix-turn-helix domain | G-quadruplex DNA unwinding | unknown | Helix-hairpin-helix containing domain | unknown | four-way junction helicase activity | unknown | unknown | unknown | PIF1-like helicase | Superfamily I DNA and RNA helicases and helicase subunits | DNA helicase | A helicase nuclease that prepares dsDNA breaks (DSB) for recombinational DNA repair. Binds to DSBs and unwinds DNA via a highly rapid and processive ATP-dependent bidirectional helicase activity. Unwinds dsDNA until it encounters a Chi (crossover hotspot instigator) sequence from the 3' direction. Cuts ssDNA a few nucleotides 3' to the Chi site. The properties and activities of the enzyme are changed at Chi. The Chi-altered holoenzyme produces a long 3'-ssDNA overhang and facilitates RecA-binding to the ssDNA for homologous DNA recombination and repair. Holoenzyme degrades any linearized DNA that is unable to undergo homologous recombination. In the holoenzyme this subunit has ssDNA-dependent ATPase and 5'-3' helicase activity. When added to pre-assembled RecBC greatly stimulates nuclease activity and augments holoenzyme processivity. Negatively regulates the RecA-loading ability of RecBCD | F22: AAA_30 | G22: 13.70782 | N22: early high expressed | O22: 300 | P22: -1 | Q22: 18682 | R22: 19581 | S22: =2003807+Q22 -> 2022489 | T22: =2003808+R22 -> 2023389 | W22: 97.312297 | X22: 611.6 | Y22: pre_induc
A23: contig_536_22 | B23: 22 | C23: no_hit | D23: 0 | E23: no_hit | F23: no_hit | G23: 0 | N23: TIR 1 start; early high expressed | O23: 1303 | P23: -1 | Q23: 20490 | R23: 24398 | S23: =2003807+Q23 -> 2024297 | T23: =2003808+R23 -> 2028206 | W23: 50.09561 | X23: 1345.3 | Y23: pre_induc
A24: contig_536_23 | B24: 23 | C24: no_hit | D24: 0 | E24: no_hit | F24: no_hit | G24: 0 | N24: early high expressed | O24: 213 | P24: -1 | Q24: 24401 | R24: 25039 | S24: =2003807+Q24 -> 2028208 | T24: =2003808+R24 -> 2028847 | W24: 716.52141 | X24: 3162 | Y24: pre_induc
A25: contig_536_24 | B25: 24 | C25: no_hit | D25: 0 | E25: no_hit | F25: no_hit | G25: 0 | O25: 62 | P25: 1 | Q25: 29503 | R25: 29688 | S25: =2003807+Q25 -> 2033310 | T25: =2003808+R25 -> 2033496 | W25: 0.8973179 | X25: 1.3
A26: contig_536_25 | B26: 25 | C26: no_hit | D26: 0 | E26: no_hit | F26: no_hit | G26: 0 | O26: 159 | P26: -1 | Q26: 29653 | R26: 30129 | S26: =2003807+Q26 -> 2033460 | T26: =2003808+R26 -> 2033937 | W26: 24.079208 | X26: 75.2
A27: contig_536_26 | B27: 26 | C27: no_hit | D27: 0 | E27: no_hit | F27: no_hit | G27: 0 | O27: 47 | P27: 1 | Q27: 30829 | R27: 30969 | S27: =2003807+Q27 -> 2034636 | T27: =2003808+R27 -> 2034777 | W27: 25.077644 | X27: 24.7
A28: contig_536_27 | B28: 27 | C28: no_hit | D28: 0 | E28: no_hit | F28: no_hit | G28: 0 | O28: 251 | P28: 1 | Q28: 31467 | R28: 32219 | S28: =2003807+Q28 -> 2035274 | T28: =2003808+R28 -> 2036027 | W28: 18.947865 | X28: 96.5
A29: contig_536_28 | B29: 28 | C29: no_hit | D29: 0 | E29: no_hit | F29: no_hit | G29: 0 | O29: 57 | P29: -1 | Q29: 32569 | R29: 32739 | S29: =2003807+Q29 -> 2036376 | T29: =2003808+R29 -> 2036547 | W29: 10.730382 | X29: 12.6
A30: contig_536_29 | B30: 29 | C30: no_hit | D30: 0 | E30: no_hit | F30: no_hit | G30: 0 | N30: TIR 1 end | O30: 95 | P30: -1 | Q30: 33143 | R30: 33427 | S30: =2003807+Q30 -> 2036950 | T30: =2003808+R30 -> 2037235 | W30: 6.6609876 | X30: 12.7
A31: contig_536_30 | B31: 30 | C31: no_hit | D31: 0 | E31: no_hit | F31: no_hit | G31: 0 | O31: 116 | P31: 1 | Q31: 33978 | R31: 34325 | S31: =2003807+Q31 -> 2037785 | T31: =2003808+R31 -> 2038133 | W31: 44.252759 | X31: 103.1
A32: contig_536_31 | B32: 31 | C32: no_hit | D32: 0 | E32: no_hit | F32: no_hit | G32: 0 | O32: 45 | P32: -1 | Q32: 34662 | R32: 34796 | S32: =2003807+Q32 -> 2038469 | T32: =2003808+R32 -> 2038604 | W32: 95.093289 | X32: 89.4
A33: contig_536_32 | B33: 32 | C33: no_hit | D33: 0 | E33: no_hit | F33: no_hit | G33: 0 | O33: 97 | P33: -1 | Q33: 34854 | R33: 35144 | S33: =2003807+Q33 -> 2038661 | T33: =2003808+R33 -> 2038952 | W33: 14.629262 | X33: 28.4
A34: contig_536_33 | B34: 33 | C34: no_hit | D34: 0 | E34: no_hit | F34: no_hit | G34: 0 | O34: 177 | P34: 1 | Q34: 36556 | R34: 37086 | S34: =2003807+Q34 -> 2040363 | T34: =2003808+R34 -> 2040894 | W34: 8.1042005 | X34: 29.6
A35: contig_536_34 | B35: 34 | C35: no_hit | D35: 0 | E35: no_hit | F35: no_hit | G35: 0 | O35: 178 | P35: -1 | Q35: 37338 | R35: 37871 | S35: =2003807+Q35 -> 2041145 | T35: =2003808+R35 -> 2041679 | W35: 5.9505576 | X35: 22
A36: contig_536_35 | B36: 35 | C36: no_hit | D36: 0 | E36: no_hit | F36: no_hit | G36: 0 | O36: 174 | P36: 1 | Q36: 37874 | R36: 38395 | S36: =2003807+Q36 -> 2041681 | T36: =2003808+R36 -> 2042203 | W36: 11.680902 | X36: 37.3
A37: contig_536_36 | B37: 36 | C37: no_hit | D37: 0 | E37: no_hit | F37: no_hit | G37: 0 | O37: 44 | P37: -1 | Q37: 38773 | R37: 38904 | S37: =2003807+Q37 -> 2042580 | T37: =2003808+R37 -> 2042712 | W37: 0.481057 | X37: 0.5
A38: contig_536_37 | B38: 37 | C38: no_hit | D38: 0 | E38: no_hit | F38: no_hit | G38: 0 | O38: 128 | P38: -1 | Q38: 39177 | R38: 39560 | S38: =2003807+Q38 -> 2042984 | T38: =2003808+R38 -> 2043368 | W38: 12077.39 | X38: 29703.4
A39: contig_536_38 | B39: 38 | C39: no_hit | D39: 0 | E39: no_hit | F39: no_hit | G39: 0 | O39: 70 | P39: -1 | Q39: 39560 | R39: 39769 | S39: =2003807+Q39 -> 2043367 | T39: =2003808+R39 -> 2043577 | W39: 33.516795 | X39: 47.1
A40: contig_536_39 | B40: 39 | C40: no_hit | D40: 0 | E40: no_hit | F40: no_hit | G40: 0 | O40: 136 | P40: -1 | Q40: 39770 | R40: 40177 | S40: =2003807+Q40 -> 2043577 | T40: =2003808+R40 -> 2043985 | W40: 30.688597 | X40: 73.9 | Y40: post_induc
...

Sheet hhpred proteomics
A1: gene | B1: Category | C1: Nr | D1: Hit | E1: Name | F1: Probability | G1: E-value | H1: Score | I1: SS | J1: Aligned cols | K1: Target Length
A2: contig_536_46 | B2: Unknown | C2: 1 | D2: 7BVW_A | E2: AT5G66160 protein; C3H2C3, ring finger, E3 ligase, TRANSPORT PROTEIN; 2.1A {Arabidopsis thaliana} | F2: 23.78 | G2: 110 | H2: 15.52 | I2: 1.1 | J2: 14 | K2: 82
C3: 2 | D3: 1I27_A | E3: TRANSCRIPTION FACTOR IIF; GENERAL TRANSCRIPTION FACTOR, RAP74, RAP30, TFIIF, RNA POLYMERASE II, WINGED-HELIX DOMAIN, TRA | F3: 20.57 | G3: 99 | H3: 21.86 | I3: 0.7 | J3: 12 | K3: 73
A4: contig_536_74 | B4: Mobile elements | C4: 1 | D4: 7Q5B_C | E4: Transposon Ty3-G Gag-Pol polyprotein; Transcription, RNA Pol III, Ty3 Retrotransposon, Intasome, DNA BINDING PROTEIN;{Sa | F4: 100 | G4: 3.9e-56 | H4: 650.06 | I4: 100.9 | J4: 1150 | K4: 1547
C5: 2 | D5: P03359 | E5: POL_WMSV Gag-Pol polyprotein OS=Woolly monkey sarcoma virus OX=11970 GN=pol PE=3 SV=2 | F5: 100 | G5: 2e-53 | H5: 619.81 | I5: 88.6 | J5: 889 | K5: 1687
C6: 3 | D6: P10272 | E6: POL_BAEVM Gag-Pol polyprotein OS=Baboon endogenous virus (strain M7) OX=11764 GN=pol PE=3 SV=2 | F6: 100 | G6: 7.5e-54 | H6: 619.25 | I6: 81.9 | J6: 895 | K6: 1727
C7: 4 | D7: O92815 | E7: POL_WDSV Gag-Pol polyprotein OS=Walleye dermal sarcoma virus OX=39720 GN=gag-pol PE=1 SV=2 | F7: 100 | G7: 6.5e-49 | H7: 580.91 | I7: 95.7 | J7: 1137 | K7: 1752
C8: 5 | D8: P03355 | E8: POL_MLVMS Gag-Pol polyprotein OS=Moloney murine leukemia virus (isolate Shinnick) OX=928306 GN=gag-pol PE=1 SV=5 | F8: 100 | G8: 3e-46 | H8: 551.45 | I8: 86 | J8: 1115 | K8: 1738
A9: contig_536_76 | B9: Mobile elements | C9: 1 | D9: 8GKH_P | E9: Maltodextrin-binding protein (Fragment),OrfB_Zn_ribbon domain-containing protein; Fanzor, Eukaryotic, RNA-guided, nuclea | F9: 100 | G9: 1.1e-60 | H9: 570.41 | I9: 49.2 | J9: 584 | K9: 1032
B10: Fanzor_C_nuclease | C10: 2 | D10: Q5UPF5 | E10: YL079_MIMIV Putative transposase L79 OS=Acanthamoeba polyphaga mimivirus OX=212035 GN=MIMI_L79 PE=3 SV=1 | F10: 99.5 | G10: 1.8e-13 | H10: 152.19 | I10: 11.8 | J10: 104 | K10: 520
C11: 3 | D11: O41107 | E11: A625_PBCV1 Putative transposase A625R OS=Paramecium bursaria Chlorella virus 1 OX=10506 GN=A625R PE=3 SV=1 | F11: 99.49 | G11: 3e-13 | H11: 147.27 | I11: 12.6 | J11: 110 | K11: 433
C12: 4 | D12: Q5URB4 | E12: YR186_MIMIV Putative transposase R186 OS=Acanthamoeba polyphaga mimivirus OX=212035 GN=MIMI_R186 PE=3 SV=1 | F12: 99.46 | G12: 9.5e-13 | H12: 145.16 | I12: 14.1 | J12: 221 | K12: 482
C13: 5 | D13: Q3V4S9 | E13: Y409_ATV Putative transposase ORF409 OS=Acidianus two-tailed virus OX=315953 PE=3 SV=1 | F13: 99.42 | G13: 1.4e-12 | H13: 140.88 | I13: 11.6 | J13: 207 | K13: 409
A14: contig_536_100 | B14: Metabolism, miscellaneous | C14: 1 | D14: 5LW3_A | E14: Poly(beta-D-mannuronate) C5 epimerase 6; C-5 Epimerase, isomerase; HET: B3P; 1.19A {Azotobacter vinelandii} | F14: 99.84 | G14: 1.8e-17 | H14: 183.93 | I14: 35.3 | J14: 261 | K14: 387
C15: 2 | D15: 3ZPP_A | E15: CELL WALL SURFACE ANCHOR FAMILY PROTEIN; CELL ADHESION, PFBA, SURFACE ADHESIN, SP1833, MSCRAMM; 2.28A {STREPTOCOCCUS PNE | F15: 99.8 | G15: 2.7e-16 | H15: 178.13 | I15: 35.5 | J15: 321 | K15: 443
C16: 3 | D16: 5ZRU_C | E16: Alpha-1,3-glucanase; Agl-KA GH87, HYDROLASE; HET: CA, SO4, PE5; 1.833A {Bacillus circulans} | F16: 99.8 | G16: 1.6e-15 | H16: 186.36 | I16: 45.1 | J16: 325 | K16: 578
C17: 4 | D17: 7JWF_B | E17: Glycoside hydrolase family 110; beta helix, HYDROLASE; HET: GAL, EDO, EPE, ACT, MLT, CL, IOD, GLA, PG4; 2.187A {Pseudoal | F17: 99.75 | G17: 8e-15 | H17: 180.26 | I17: 39.2 | J17: 322 | K17: 620
C18: 5 | D18: 7C7D_A | E18: alpha-1,3-glucanase; glycosidase, HYDROLASE; HET: 1PE; 1.16A {Streptomyces thermodiastaticus} | F18: 99.75 | G18: 1.1e-14 | H18: 178.22 | I18: 40.1 | J18: 336 | K18: 610
A19: contig_536_101 | B19: Metabolism, miscellaneous | C19: 1 | D19: 3WX7_A | E19: Chitin oligosaccharide deacetylase; oligosaccharide deacetylace, carbohydrate-binding, HYDROLASE; HET: GOL; 1.349A {Vibr | F19: 96.54 | G19: 0.017 | H19: 71.22 | I19: 9.4 | J19: 86 | K19: 402
C20: 2 | D20: 3WX7_A | E20: Chitin oligosaccharide deacetylase; oligosaccharide deacetylace, carbohydrate-binding, HYDROLASE; HET: GOL; 1.349A {Vibr | F20: 96.24 | G20: 0.034 | H20: 68.69 | I20: 9.6 | J20: 84 | K20: 402
C21: 3 | D21: 3WX7_A | E21: Chitin oligosaccharide deacetylase; oligosaccharide deacetylace, carbohydrate-binding, HYDROLASE; HET: GOL; 1.349A {Vibr | F21: 96.03 | G21: 0.056 | H21: 66.94 | I21: 10 | J21: 93 | K21: 402
C22: 4 | D22: 3WX7_A | E22: Chitin oligosaccharide deacetylase; oligosaccharide deacetylace, carbohydrate-binding, HYDROLASE; HET: GOL; 1.349A {Vibr | F22: 95.9 | G22: 0.059 | H22: 66.77 | I22: 9.4 | J22: 98 | K22: 402
C23: 5 | D23: SM00495 | E23: ChtBD3; Chitin-binding domain type 3 | F23: 91.51 | G23: 0.91 | H23: 37.43 | I23: 5.1 | J23: 40 | K23: 41
A24: contig_536_102 | B24: Metabolism, miscellaneous | C24: 1 | D24: 3WX7_A | E24: Chitin oligosaccharide deacetylase; oligosaccharide deacetylace, carbohydrate-binding, HYDROLASE; HET: GOL; 1.349A {Vibr | F24: 91.54 | G24: 0.93 | H24: 60.56 | I24: 7.9 | J24: 91 | K24: 402
C25: 2 | D25: 3WX7_A | E25: Chitin oligosaccharide deacetylase; oligosaccharide deacetylace, carbohydrate-binding, HYDROLASE; HET: GOL; 1.349A {Vibr | F25: 89.97 | G25: 1.4 | H25: 59.02 | I25: 7.5 | J25: 91 | K25: 402
C26: 3 | D26: 3WX7_A | E26: Chitin oligosaccharide deacetylase; oligosaccharide deacetylace, carbohydrate-binding, HYDROLASE; HET: GOL; 1.349A {Vibr | F26: 86.08 | G26: 5.9 | H26: 53.62 | I26: 9.5 | J26: 115 | K26: 402
C27: 4 | D27: 3WX7_A | E27: Chitin oligosaccharide deacetylase; oligosaccharide deacetylace, carbohydrate-binding, HYDROLASE; HET: GOL; 1.349A {Vibr | F27: 84.34 | G27: 4.7 | H27: 54.46 | I27: 7.5 | J27: 90 | K27: 402
C28: 5 | D28: 7R5K_V0 | E28: Nuclear pore complex protein Nup214; multiprotein complex, nucleocytoplasmic transport, TRANSPORT PROTEIN; 12.0A {Homo s | F28: 69.87 | G28: 25 | H28: 56.78 | I28: 8.6 | J28: 89 | K28: 2090
A29: contig_536_107 | B29: Transcription, replication | C29: 1 | D29: 1W36_G | E29: EXODEOXYRIBONUCLEASE V ALPHA CHAIN; RECOMBINATION, HELICASE, NUCLEASE, HYDROLASE, DNA REPAIR; 3.1A {ESCHERICHIA COLI} SC | F29: 99.97 | G29: 4.7e-30 | H29: 319.57 | I29: 32 | J29: 342 | K29: 608
C30: 2 | D30: 3E1S_A | E30: Exodeoxyribonuclease V, subunit RecD; alpha and beta protein, ATP-binding, Nucleotide-binding, HYDROLASE; 2.2A {Deinococ | F30: 99.97 | G30: 1.7e-28 | H30: 301.81 | I30: 31.6 | J30: 338 | K30: 574
C31: 3 | D31: 8BNS_C | E31: AAA ATPase; Helicase Thermophile, HYDROLASE; HET: ADP; 3.24A {Sulfurihydrogenibium sp. YO3AOP1} | F31: 99.96 | G31: 3e-28 | H31: 293.84 | I31: 27.8 | J31: 351 | K31: 517
C32: 4 | D32: 7BIL_B | E32: PIF1 helicase; DNA helicase, HYDROLASE; HET: ADP, ALF; 2.21A {Thermus oshimai JL-2} | F32: 99.96 | G32: 4.1e-28 | H32: 292.98 | I32: 25.8 | J32: 382 | K32: 507
C33: 5 | D33: 8BNV_A | E33: AAA family ATPase; Helicase Thermophile, HYDROLASE; HET: GOL; 2.86A {Deferribacter desulfuricans} | F33: 99.95 | G33: 4.5e-26 | H33: 271.63 | I33: 29 | J33: 349 | K33: 510
A34: contig_536_113 | B34: Unknown | C34: 1 | D34: 5SY7_B | E34: Neuronal PAS domain-containing protein 3; bHLH-PAS protein, transcription factor, heterodimeric complex, transcription-D | F34: 16.02 | G34: 110 | H34: 23.06 | I34: 0.1 | J34: 34 | K34: 410
A35: contig_536_120 | B35: Unknown | C35: 1 | D35: 8ANV_F | E35: Arbitrium putative lysogeny regulator; Arbitrium, Phi3T, lysis-lysogeny decission, VIRAL PROTEIN; 2.2A {Bacillus phage p | F35: 63.01 | G35: 18 | H35: 25.71 | I35: 2.6 | J35: 28 | K35: 52
C36: 2 | D36: PF05130.16 | E36: ; FlgN ; FlgN protein | F36: 54.77 | G36: 88 | H36: 21.88 | I36: 4.8 | J36: 63 | K36: 142
C37: 3 | D37: 2BO4_D | E37: MANNOSYLGLYCERATE SYNTHASE; CATALYSIS, GLYCOSYLTRANSFERASE, MANNOSE, TRANSFERASE, STEREOSELECTIVITY; HET: FLC; 1.95A {RH | F37: 45.82 | G37: 250 | H37: 23.5 | I37: 6.8 | J37: 56 | K37: 397
C38: 4 | D38: 7LV9_B | E38: Histone doublet Delta-Gamma (Delta); Structural Protein/DNA, STRUCTURAL PROTEIN, STRUCTURAL PROTEIN-DNA complex; 4.5A {M | F38: 41.13 | G38: 180 | H38: 21.69 | I38: 4.9 | J38: 47 | K38: 97
C39: 5 | D39: 1TAF_A | E39: TFIID TBP ASSOCIATED FACTOR 42; TRANSCRIPTION INITIATION, HISTONE FOLD, COMPLEX (TWO TRANSCRIPTION FACTORS); 2.0A {Droso | F39: 41.11 | G39: 81 | H39: 20.22 | I39: 2.8 | J39: 46 | K39: 68
A40: contig_536_123 | B40: Unknown | C40: 1 | D40: 6RBG_B | E40: Chain length determinant protein; membrane protein, enzyme, polysaccharide, co-polymerase; 3.0A {Escherichia coli (strai | F40: 91.82 | G40: 11 | H40: 31.54 | I40: 12.2 | J40: 150 | K40: 341
...

Sheet hhpred pre induction genes
A1: gene | B1: expr_cluster | C1: Nr | D1: Hit | E1: Name | F1: Probability | G1: E-value | H1: Score | I1: SS | J1: Aligned cols | K1: Target Length
A2: contig_536_20 | B2: pre_induc | C2: 1 | D2: 5O6B_A | E2: ATP-dependent DNA helicase PIF1; Helicase SF1 ssDNA ATP analog, HYDROLASE; HET: ALF, ADP; 2.029A {Saccharomyces cerevisi | F2: 92.69 | G2: 0.42 | H2: 42.11 | I2: 4.6 | J2: 111 | K2: 545
C3: 2 | D3: 7OTJ_A | E3: ATP-dependent DNA helicase PIF1; Helicase Pif1, HYDROLASE; HET: K, PO4, ALF, ADP; 2.58A {Candida albicans} | F3: 90.79 | G3: 0.41 | H3: 40.59 | I3: 2.4 | J3: 119 | K3: 518
C4: 3 | D4: Q9QSK3 | E4: VF030_IIV6 Uncharacterized protein 030L OS=Invertebrate iridescent virus 6 OX=176652 GN=IIV6-030L PE=3 SV=1 | F4: 80.6 | G4: 1.1 | H4: 39.04 | I4: 0 | J4: 119 | K4: 530
C5: 4 | D5: Q196V4 | E5: VF030_IIV3 Uncharacterized protein 106R OS=Invertebrate iridescent virus 3 OX=345201 GN=IIV3-106R PE=3 SV=1 | F5: 75.16 | G5: 3.3 | H5: 35.54 | I5: 1.2 | J5: 78 | K5: 473
C6: 5 | D6: 8BNS_C | E6: AAA ATPase; Helicase Thermophile, HYDROLASE; HET: ADP; 3.24A {Sulfurihydrogenibium sp. YO3AOP1} | F6: 63.24 | G6: 4.2 | H6: 35.24 | I6: -0.5 | J6: 22 | K6: 517
A7: contig_536_21 | B7: pre_induc | C7: 1 | D7: 8BNS_C | E7: AAA ATPase; Helicase Thermophile, HYDROLASE; HET: ADP; 3.24A {Sulfurihydrogenibium sp. YO3AOP1} | F7: 99.64 | G7: 1.4e-15 | H7: 125.26 | I7: 9 | J7: 230 | K7: 517
C8: 2 | D8: P03214 | E8: HELI_EBVB9 DNA replication helicase OS=Epstein-Barr virus (strain B95-8) OX=10377 GN=HELI PE=3 SV=1 | F8: 99.56 | G8: 4.9e-15 | H8: 135.82 | I8: 4.9 | J8: 232 | K8: 809
C9: 3 | D9: Q2HR89 | E9: HELI_HHV8P DNA replication helicase OS=Human herpesvirus 8 type P (isolate GK18) OX=868565 GN=HELI PE=3 SV=1 | F9: 99.54 | G9: 7.3e-15 | H9: 135.11 | I9: 4.6 | J9: 238 | K9: 788
C10: 4 | D10: Q01014 | E10: HELI_SHV21 DNA replication helicase OS=Saimiriine herpesvirus 2 (strain 11) OX=10383 GN=HELI PE=3 SV=1 | F10: 99.52 | G10: 2.9e-14 | H10: 130.7 | I10: 6.2 | J10: 244 | K10: 781
C11: 5 | D11: 8BNV_A | E11: AAA family ATPase; Helicase Thermophile, HYDROLASE; HET: GOL; 2.86A {Deferribacter desulfuricans} | F11: 99.5 | G11: 2.5e-13 | H11: 109.41 | I11: 9.1 | J11: 230 | K11: 510
A12: contig_536_22 | B12: pre_induc | C12: 1 | D12: 8BPO_s2 | E12: S phase cyclin A-associated protein in the endoplasmic reticulum; tubulin auto-regulation mRNA decay translation SCAPER, | F12: 94.41 | G12: 39 | H12: 45 | I12: 27.4 | J12: 193 | K12: 1411
C13: 2 | D13: 7C4J_C | E13: Transcription regulatory protein SNF6; SWI/SNF remodeling, Swi-Snf complex, nucleosome, DNA BINDING PROTEIN; 2.89A {Sacc | F13: 90.74 | G13: 6.8 | H13: 45.28 | I13: 12.2 | J13: 134 | K13: 332
C14: 3 | D14: 8J6S_K | E14: Chromatin assembly factor 1 subunit A; REPLICATION-DNA COMPLEX; 3.8A {Homo sapiens} | F14: 88.41 | G14: 100 | H14: 39.82 | I14: 20.6 | J14: 129 | K14: 956
C15: 4 | D15: PF11932.13 | E15: ; DUF3450 ; Protein of unknown function (DUF3450) | F15: 86.44 | G15: 15 | H15: 36.13 | I15: 9.9 | J15: 144 | K15: 240
C16: 5 | D16: 7UK1_B | E16: Splicing factor, proline- and glutamine-rich; Polypyridimine-binding splicing factor, 5'-polyuridine negative-sense (5'- | F16: 83.44 | G16: 21 | H16: 37.75 | I16: 10 | J16: 61 | K16: 412
A17: contig_536_23 | B17: pre_induc | C17: 1 | D17: 6R4L_A | E17: NPC intracellular cholesterol transporter 1-related protein 1; Vacuole, Ergosterol, LIPID TRANSPORT, membrane protein; H | F17: 21.08 | G17: 150 | H17: 29.39 | I17: 2.2 | J17: 26 | K17: 1198
A18: contig_536_41 | B18: pre_induc | C18: 1 | D18: PF22560.1 | E18: ; GMT-wHTH ; GMT-like wHTH domain | F18: 29.59 | G18: 170 | H18: 18.03 | I18: 2.8 | J18: 24 | K18: 85
C19: 2 | D19: 8GLV_As | E19: Flagellar outer dynein arm light chain 2; cilia, microtubule, dynein, MOTOR PROTEIN; HET: GDP, MG, GTP; 3.1A {Chlamydomo | F19: 28.02 | G19: 52 | H19: 22.23 | I19: 0.4 | J19: 75 | K19: 136
C20: 3 | D20: PF12119.13 | E20: ; DUF3581 ; Protein of unknown function (DUF3581) | F20: 21.34 | G20: 67 | H20: 27.72 | I20: 0 | J20: 9 | K20: 217
A21: contig_536_42 | B21: not DEG | C21: 1 | D21: 5KOL_A | E21: Uncharacterized protein; CinA, Competence-damaged protein, outer membrane biogenesis, structural genomics, CSGID, Center | F21: 31.15 | G21: 36 | H21: 21.42 | I21: 0.1 | J21: 15 | K21: 173
C22: 2 | D22: PF02059.20 | E22: ; IL3 ; Interleukin-3 | F22: 28.78 | G22: 75 | H22: 23.43 | I22: 1.3 | J22: 26 | K22: 112
C23: 3 | D23: PF10871.13 | E23: ; DUF2748 ; Protein of unknown function (DUF2748) | F23: 24.95 | G23: 91 | H23: 28.26 | I23: 1.4 | J23: 17 | K23: 433
C24: 4 | D24: 3VZ9_B | E24: Uncharacterized protein; RWD domain, kinetochore component, chromosome segregation, Ndc80 complex, CELL CYCLE; 1.03A {Ga | F24: 22.71 | G24: 210 | H24: 18.33 | I24: 2.4 | J24: 38 | K24: 106
C25: 5 | D25: 2L3O_A | E25: Interleukin 3; cytokine, Murine Interleukin-3; NMR {Mus musculus} SCOP: a.26.1.0 | F25: 20.56 | G25: 130 | H25: 22.73 | I25: 1.3 | J25: 26 | K25: 127
A26: contig_536_43 | B26: pre_induc | C26: 1 | D26: PF11027.13 | E26: ; DUF2615 ; Protein of unknown function (DUF2615) | F26: 32 | G26: 74 | H26: 24.79 | I26: 1.9 | J26: 30 | K26: 97
C27: 2 | D27: 3BCH_A | E27: 40S ribosomal protein SA; laminin receptor, p40 ribosomal protein, Acetylation, Cytoplasm, Phosphorylation, Polymorphism | F27: 30.53 | G27: 64 | H27: 26.47 | I27: 1.4 | J27: 31 | K27: 253
C28: 3 | D28: 8DU5_B | E28: Sialidase-1; sialic acid, sialidase, glycosidase, lysosome, HYDROLASE; HET: BMA, NAG, MAN, FUC; 3.5A {Mus musculus} | F28: 29.85 | G28: 62 | H28: 23.9 | I28: 1.1 | J28: 12 | K28: 378
C29: 4 | D29: 4N4G_A | E29: Zinc finger MYND domain-containing protein 11; tandem bromodomain-zinc finger-PWWP motif, histone H3.3-specific, TRANSCR | F29: 28.24 | G29: 93 | H29: 22.46 | I29: 1.7 | J29: 33 | K29: 252
C30: 5 | D30: PF21432.2 | E30: ; 56B_RHH ; 56B-like, Ribbon-helix-helix | F30: 28 | G30: 170 | H30: 15.46 | I30: 2.3 | J30: 22 | K30: 33
A31: contig_536_57 | B31: pre_induc | C31: 1 | D31: P90212 | E31: OPEP3_NPVOP OPEP-3 protein OS=Orgyia pseudotsugata multicapsid polyhedrosis virus OX=262177 GN=OPEP-3 PE=4 SV=1 | F31: 45.21 | G31: 18 | H31: 34.39 | I31: 0.5 | J31: 27 | K31: 285
C32: 2 | D32: 1GTF_K | E32: TRP RNA-BINDING ATTENUATION PROTEIN (TRAP); RNA BINDING PROTEIN-RNA COMPLEX, TRANSCRIPTION ATTENUATION, RNA-BINDING PROT | F32: 25.69 | G32: 85 | H32: 25.26 | I32: 1.3 | J32: 21 | K32: 74
C33: 3 | D33: 4J0W_A | E33: U3 small nucleolar RNA-interacting protein 2; Beta-Propeller, WD domain, RNA Binding protein, preribosome; 1.7A {Homo sa | F33: 25.6 | G33: 240 | H33: 20 | I33: 3.2 | J33: 75 | K33: 343
C34: 4 | D34: PF02081.20 | E34: ; TrpBP ; Tryptophan RNA-binding attenuator protein | F34: 23.16 | G34: 100 | H34: 24.54 | I34: 1.2 | J34: 21 | K34: 68
C35: 5 | D35: 8CM1_A | E35: Outer-membrane lipoprotein LolB; Localization of Lipoproteins, PROTEIN TRANSPORT; 1.46A {Vibrio cholerae} | F35: 22.83 | G35: 230 | H35: 21.73 | I35: 3 | J35: 30 | K35: 212
A36: contig_536_58 | B36: pre_induc | C36: 1 | D36: 3TUL_A | E36: Cell invasion protein sipB; translocator, type three secretion system, coiled-coil, virulence, CELL INVASION; HET: MSE; | F36: 75.35 | G36: 120 | H36: 28.59 | I36: 12.3 | J36: 139 | K36: 158
C37: 2 | D37: 7R5K_I3 | E37: Nucleoporin p58/p45; multiprotein complex, nucleocytoplasmic transport, TRANSPORT PROTEIN; 12.0A {Homo sapiens} | F37: 58 | G37: 680 | H37: 30.84 | I37: 16.3 | J37: 154 | K37: 599
C38: 3 | D38: 1TQQ_C | E38: Outer membrane protein tolC; Beta-barrel, alpha-barrel, transport protein; 2.75A {Escherichia coli} SCOP: f.5.1.1 | F38: 56 | G38: 320 | H38: 26.47 | I38: 16.9 | J38: 163 | K38: 471
C39: 4 | D39: 6U94_A | E39: RND efflux system, outer membrane lipoprotein, NodT family; outer membrane lipoprotein, NodT family, Structural Genomics | F39: 53.71 | G39: 520 | H39: 28.12 | I39: 13.9 | J39: 107 | K39: 600
C40: 5 | D40: 6U94_A | E40: RND efflux system, outer membrane lipoprotein, NodT family; outer membrane lipoprotein, NodT family, Structural Genomics | F40: 51.78 | G40: 550 | H40: 27.9 | I40: 13.9 | J40: 107 | K40: 600
...

Sheet hhpred chr_16
A1: gene | B1: Nr | C1: Hit | D1: Name | E1: Probability | F1: E-value | G1: Score | H1: SS | I1: Aligned cols | J1: Target Length
A2: contig_437_1 | B2: 1 | C2: 8BPO_s2 | D2: S phase cyclin A-associated protein in the endoplasmic reticulum; tubulin auto-regulation mRNA decay translation SCAPER, | E2: 90.46 | F2: 110 | G2: 40.52 | H2: 27.6 | I2: 193 | J2: 1411
B3: 2 | C3: 7C4J_C | D3: Transcription regulatory protein SNF6; SWI/SNF remodeling, Swi-Snf complex, nucleosome, DNA BINDING PROTEIN; 2.89A {Sacc | E3: 89.26 | F3: 11 | G3: 42.98 | H3: 12.2 | I3: 134 | J3: 332
B4: 3 | C4: PF11932.13 | D4: ; DUF3450 ; Protein of unknown function (DUF3450) | E4: 86.07 | F4: 18 | G4: 34.89 | H4: 10.1 | I4: 144 | J4: 240
B5: 4 | C5: 7NRC_A | D5: GCN1; Ribosome, Disome, GCN1, Translation, GAAC, ISR, Rbg2, Gir2; HET: 5CT; 3.9A {Saccharomyces cerevisiae S288C} | E5: 82.97 | F5: 11 | G5: 48.5 | H5: 8.9 | I5: 198 | J5: 1209
B6: 5 | C6: 8PPL_Iu | D6: Eukaryotic translation initiation factor 3 subunit A; Nsp1, MERS, SARS, SARS-CoV2, ribosome, 40S ribosomal subunit, tran | E6: 80.7 | F6: 340 | G6: 36.75 | H6: 22.1 | I6: 318 | J6: 1382
A7: contig_437_2 | B7: 1 | C7: SM00547 | D7: ZnF_RBZ; Zinc finger domain | E7: 78.85 | F7: 2.7 | G7: 19.21 | H7: 1 | I7: 25 | J7: 25
B8: 2 | C8: 6U75_B | D8: E3 SUMO-protein ligase SIZ2; SUMO, SIGNAL TRANSDUCTION, REPLICATION, RING E3, PIAS, SIZ, UBIQUITIN, UBC9, LIGASE, METAL- | E8: 50.75 | F8: 10 | G8: 31.4 | H8: -0.2 | I8: 35 | J8: 269
B9: 3 | C9: PF16988.10 | D9: ; Vps36-NZF-N ; Vacuolar protein sorting 36 NZF-N zinc-finger domain | E9: 38.45 | F9: 30 | G9: 25.16 | H9: 0.6 | I9: 14 | J9: 68
B10: 4 | C10: PF19134.5 | D10: ; DUF5817 ; Domain of unknown function (DUF5817) | E10: 35.85 | F10: 63 | G10: 18.24 | H10: 1.6 | I10: 51 | J10: 57
B11: 5 | C11: SM00734 | D11: ZnF_Rad18; Rad18-like CCHC zinc finger | E11: 34.41 | F11: 26 | G11: 19.93 | H11: -0.1 | I11: 9 | J11: 24
A12: contig_437_3 | C12: GVOGm0054 | D12: PolB
A13: contig_437_4 | B13: 1 | C13: 3WX7_A | D13: Chitin oligosaccharide deacetylase; oligosaccharide deacetylace, carbohydrate-binding, HYDROLASE; HET: GOL; 1.349A {Vibr | E13: 90.88 | F13: 0.51 | G13: 62.28 | H13: 4.6 | I13: 91 | J13: 402
B14: 2 | C14: 3WX7_A | D14: Chitin oligosaccharide deacetylase; oligosaccharide deacetylace, carbohydrate-binding, HYDROLASE; HET: GOL; 1.349A {Vibr | E14: 86.04 | F14: 2.5 | G14: 56.32 | H14: 6.1 | I14: 91 | J14: 402
B15: 3 | C15: 3WX7_A | D15: Chitin oligosaccharide deacetylase; oligosaccharide deacetylace, carbohydrate-binding, HYDROLASE; HET: GOL; 1.349A {Vibr | E15: 85.41 | F15: 4.6 | G15: 54.11 | H15: 7.9 | I15: 87 | J15: 402
